Workbook

Sheet Flows
A1: Flow ID | B1: Device ID | C1: Device | D1: Category ID | E1: Category | F1: Row in device sheet | G1: Phase | H1: Dataflow | I1: data_type | J1: purpose | K1: action | L1: source | M1: handling_context | N1: Constraints | O1: Core rule group | P1: Control type | Q1: Necessity | R1: Control cue(s) | S1: Control note (draft) | T1: Evidence | U1: Linked sources | V1: Declaration statement ID | W1: Notes
A2: aqara-w200.setup-wi-fi-network-credential-entered-during-pairing | B2: aqara-w200 | C2: Aqara Thermostat Hub W200 | D2: thermostat | E2: Thermostat | F2: 2 | G2: setup | H2: Setup: Wi-Fi network credential entered during pairing | I2: pat:networkCredentialData | J2: pat:deviceSetup | K2: ppd:collection | L2: ppd:userProvided | M2: ppd:householdContext | O2: ck-8d3ef5b3 | P2: setup_step | Q2: required_for_feature | S2: You enter your Wi-Fi password when pairing the thermostat; it needs it to get online. | T2: source_linked | U2: aqara-w200.src1; aqara-w200.src6 | V2: network-credential-data-device-setup-collection-household-context | W2: Round 3: Manual also offers 'Skip' for network setup and says to configure the device locally, so Wi-Fi may be needed for online/app/Matter features rather than for local thermostat operation. Left as the team set it; consider whether necessity should be optional. Necessity is inferred from what the flow does; no source states it.
A3: aqara-w200.setup-aqara-account-identifiers-email-phone-username-password | B3: aqara-w200 | C3: Aqara Thermostat Hub W200 | D3: thermostat | E3: Thermostat | F3: 3 | G3: setup | H3: Setup: Aqara account identifiers (email/phone/username/password/social sign-in) | I3: ppd:identifierData | J3: pat:accountSetup | K3: ppd:collection | L3: ppd:userProvided | M3: pat:aqaraService | O3: ck-a323000c | P3: setup_step | Q3: required_for_feature | S3: You create or sign in to an Aqara account during setup. | T3: source_linked | U3: aqara-w200.src2; aqara-w200.src6 | V3: identifier-data-account-setup-collection-aqara-service | W3: Round 3: Manual: 'Before using this product, you need to download the Aqara Home app and register an account.' (seen once, via a summarised fetch). Setup also offers a Skip option for network setup, so basic local use after skipping is not ruled out.
A4: aqara-w200.setup-hvac-system-wiring-compatibility-profile | B4: aqara-w200 | C4: Aqara Thermostat Hub W200 | D4: thermostat | E4: Thermostat | F4: 4 | G4: setup | H4: Setup: HVAC system / wiring compatibility profile | I4: pat:hvacSystemProfileData | J4: pat:deviceSetup | K4: ppd:collection | L4: ppd:userProvided | M4: ppd:householdContext | O4: ck-8d3ef5b3 | P4: setup_step | Q4: required_for_feature | S4: You answer questions about your heating and cooling wiring during setup. | T4: source_linked | U4: aqara-w200.src3 | V4: hvac-system-profile-data-device-setup-collection-household-context | W4: Round 3: Necessity is inferred from what the flow does; no source states it. Earlier note: src3 is Aqara's web compatibility checker (likely used before purchase), and it does not say where answers are stored or sent. Confirm an in-app wiring step exists, or split into a website check plus an in-app configuration flow.
A5: aqara-w200.customer-support-photo-video-attachment-upload | B5: aqara-w200 | C5: Aqara Thermostat Hub W200 | D5: thermostat | E5: Thermostat | F5: 5 | G5: runtime | H5: Customer-support photo/video attachment upload | I5: pat:visualData | J5: pat:customerSupport | K5: ppd:collection | L5: ppd:userProvided | M5: pat:aqaraService | O5: ck-8743be11 | P5: user_initiated | Q5: optional | S5: You choose whether to attach a photo or video when you contact support. You can ask Aqara to delete it afterwards, but Aqara may not always be able to. | T5: source_linked | U5: aqara-w200.src2 | V5: visual-data-customer-support-collection-aqara-service | W5: Round 3: Necessity is inferred from what the flow does; no source states it. Earlier note: Provisional: privacy policy (src2) says providing requested data is voluntary, but support may be unable to help without it; deletion is available on request. Wording came from a fetched summary of the policy - verify against the page. Retention: policy says 'as long as necessary' - left blank on purpose.
A6: aqara-w200.aqara-service-app-usage-activity-shared-with-analytics | B6: aqara-w200 | C6: Aqara Thermostat Hub W200 | D6: thermostat | E6: Thermostat | F6: 6 | G6: runtime | H6: Aqara service/app usage activity shared with analytics/advertising service providers | I6: ppd:usageData | J6: ppd:advertisingAndMarketing | K6: ppd:transfer | L6: ppd:participantObserved | M6: pat:thirdPartyServiceProvider | O6: ck-393f775e | P6: external_request | Q6: optional | R6: You may opt-out of our processing of your personal data for purposes of targeted advertising | S6: You can ask Aqara to stop using your personal data for targeted advertising by emailing privacy@Lumiunited.com. | T6: source_linked | U6: aqara-w200.src2 | V6: usage-data-advertising-and-marketing-transfer-third-party-service-provider | W6: Round 3: Changed from the team's none_documented: the privacy policy (src2) says 'You may opt-out of our processing of your personal data for purposes of targeted advertising' and names email privacy@Lumiunited.com; it also points to the DAA WebChoices tool for web cookies and a California request to opt out of sale/sharing. No in-app toggle and no analytics-specific opt-out are stated, and the opt-out wording does not clearly cover app-analytics sharing with Google/Facebook. Revert to none_documented if the team reads the row as analytics only. Necessity inferred: the thermostat does not need advertising sharing to work. Earlier note: Team set none_documented. The policy fetched for r5 (src2) mentions opt-out options for marketing communications and targeted advertising, and consent withdrawal - check whether any of these apply to this flow before keeping none_documented.
A7: aqara-w200.linked-temperature-sensor-input-for-hvac-control | B7: aqara-w200 | C7: Aqara Thermostat Hub W200 | D7: thermostat | E7: Thermostat | F7: 7 | G7: runtime | H7: Linked temperature sensor input for HVAC control | I7: pat:environmentData | J7: pat:hvacControl | K7: ppd:collection | L7: pat:linkedClimateSensor | M7: ppd:householdContext | O7: ck-35d576be | P7: user_setting | Q7: optional | R7: choose which spaces the thermostat uses | S7: You choose which linked sensors and spaces the thermostat uses. | T7: source_linked | U7: aqara-w200.src4; aqara-w200.src5 | V7: environment-data-hvac-control-collection-household-context | W7: Round 3: Necessity is inferred from what the flow does; no source states it. Earlier note: src5 says the thermostat connects to temperature, presence and other sensors and lets you choose which spaces it uses. Provisional - verify wording, and confirm a linked sensor can be removed.
A8: aqara-w200.linked-humidity-sensor-input-for-climate-balancing | B8: aqara-w200 | C8: Aqara Thermostat Hub W200 | D8: thermostat | E8: Thermostat | F8: 8 | G8: runtime | H8: Linked humidity sensor input for climate balancing | I8: pat:environmentData | J8: pat:hvacControl | K8: ppd:collection | L8: pat:linkedClimateSensor | M8: ppd:householdContext | O8: ck-35d576be | P8: user_setting | Q8: optional | R8: choose which spaces the thermostat uses | S8: You choose which linked sensors and spaces the thermostat uses. | T8: source_linked | U8: aqara-w200.src4; aqara-w200.src5 | V8: environment-data-hvac-control-collection-household-context | W8: Round 3: Necessity is inferred from what the flow does; no source states it. Earlier note: src5 says readings can be averaged across rooms and temperature/humidity soft sensors created. Provisional - verify wording.
A9: aqara-w200.built-in-mmwave-presence-occupancy-sensing | B9: aqara-w200 | C9: Aqara Thermostat Hub W200 | D9: thermostat | E9: Thermostat | F9: 9 | G9: runtime | H9: Built-in mmWave presence/occupancy sensing | I9: pat:presenceData | J9: pat:occupancyControl | K9: ppd:collection | L9: pat:mmWaveSensor | M9: ppd:householdContext | O9: ck-42c4986b | P9: none_documented | Q9: optional | T9: source_linked | U9: aqara-w200.src4; aqara-w200.src5; aqara-w200.src6; aqara-w200.src8; aqara-w200.src9 | V9: presence-data-occupancy-control-collection-household-context | W9: Round 3: Checked: product pages (src4, src5), support page (src1: videos only), W200 user manual, MacRumors review, RES Tech Today hands-on, Aqara forum user guide, privacy policy (src2). Manual: 'The built-in sensor can activate the screen as you approach.' None of them describes turning the radar off or changing its sensitivity. Necessity: heating/cooling still works with manual control or schedules; screen wake on approach and presence-based features depend on this sensor (so 'optional' follows the team's core-function reading). Necessity is inferred from what the flow does; no source states it. Earlier note: src5: radar detects human presence within about 3 m / 120 degrees, used for automations and smart control; the screen wakes as you approach. The page does not say whether the sensor can be turned off, so control stays unknown.
A10: aqara-w200.presence-data-used-for-follow-presence-adaptive-hvac | B10: aqara-w200 | C10: Aqara Thermostat Hub W200 | D10: thermostat | E10: Thermostat | F10: 10 | G10: runtime | H10: Presence data used for Follow Presence / adaptive HVAC | I10: pat:presenceData | J10: pat:adaptiveClimate | K10: ppd:use | L10: ppd:derivedFromPriorData | M10: ppd:householdContext | O10: ck-bfcbc89a | P10: none_documented | Q10: optional | T10: source_linked | U10: aqara-w200.src4; aqara-w200.src5; aqara-w200.src6; aqara-w200.src7 | V10: presence-data-adaptive-climate-use-household-context | W10: Round 3: Checked: src4, src5, user manual, Aqara forum user guide, privacy policy. The manual does not name 'Follow Presence'; the forum release note 4.5.49 lists 'Added Follow Presence function' with no on/off setting. Apple Home has its own Predictive Arrival / Adaptive Temperature settings (forum guide), but I could not confirm they control the Aqara presence-based mode in this row. Manual: if schedules are disabled 'the thermostat will only respond to manual controls', so the thermostat works without adaptive behaviour. Necessity is inferred from what the flow does; no source states it. Earlier note: src5: with a presence sensor the system switches to energy-saving mode when a room is empty; the page does not say whether this can be turned off. The term 'Follow Presence' does not appear on src5.
A11: aqara-w200.climate-environment-data-used-for-adaptive-hvac | B11: aqara-w200 | C11: Aqara Thermostat Hub W200 | D11: thermostat | E11: Thermostat | F11: 11 | G11: runtime | H11: Climate/environment data used for adaptive HVAC | I11: pat:environmentData | J11: pat:adaptiveClimate | K11: ppd:use | L11: ppd:derivedFromPriorData | M11: ppd:householdContext | O11: ck-bfcbc89a | P11: none_documented | Q11: optional | T11: source_linked | U11: aqara-w200.src4; aqara-w200.src6; aqara-w200.src7 | V11: environment-data-adaptive-climate-use-household-context | W11: Round 3: Same pages checked as the presence row above (src4, user manual, forum guide, privacy policy). No page describes a switch for adaptive use of climate data. Apple's Adaptive Temperature is configured in the Apple Home app (iOS 26 or later per the forum guide), which may be a control for the Apple-side feature only. Necessity: manual and scheduled operation work without it. Necessity is inferred from what the flow does; no source states it.
A12: aqara-w200.doorbell-visitor-snapshot-displayed-on-w200 | B12: aqara-w200 | C12: Aqara Thermostat Hub W200 | D12: thermostat | E12: Thermostat | F12: 12 | G12: runtime | H12: Doorbell visitor snapshot displayed on W200 | I12: pat:visualData | J12: pat:visitorViewing | K12: ppd:use | L12: pat:pairedDoorbell | M12: ppd:householdContext | N12: processing_boundary=ppd:inHomeOnly | O12: ck-f838b9a1 | P12: setup_step | Q12: optional | R12: Add the doorbell to your Aqara account first; the doorbell and W200 must be on the same network | S12: You choose whether to link a compatible Aqara doorbell to the thermostat in the Aqara Home app. | T12: source_linked | U12: aqara-w200.src5; aqara-w200.src7 | V12: visual-data-visitor-viewing-use-household-context | W12: Round 3: Forum guide (seen once, via a summarised fetch): doorbells and locks must be added to the Aqara account before linking, and the doorbell and W200 must be on the same LAN for the link to work. The same-LAN requirement is consistent with, but does not prove, the row's processing_boundary=inHomeOnly, which no vendor page states. The user manual does not cover doorbell linking. Whether the link can be removed later is not stated, so setup_step rather than user_setting. Necessity is inferred from what the flow does; no source states it. Earlier note: src5 supports doorbell snapshots on the thermostat screen (G410/G400 doorbells, set up in the Aqara Home app). src5 does NOT say where processing happens, so Constraints = processing_boundary=ppd:inHomeOnly is not supported by it - confirm or remove. It also does not say whether snapshots appear automatically or on request, so control stays unknown.
A13: aqara-w200.smart-lock-unlock-command-from-w200-screen | B13: aqara-w200 | C13: Aqara Thermostat Hub W200 | D13: thermostat | E13: Thermostat | F13: 13 | G13: runtime | H13: Smart-lock unlock command from W200 screen | I13: pat:lockControlCommand | J13: pat:accessControl | K13: ppd:transfer | L13: ppd:userProvided | M13: ppd:householdContext | O13: ck-6ce82887 | P13: user_initiated | Q13: optional | S13: The unlock command is sent only when you press unlock on the thermostat screen. | T13: source_linked | U13: aqara-w200.src5 | V13: lock-control-command-access-control-transfer-household-context | W13: Round 3: Necessity is inferred from what the flow does; no source states it. Earlier note: src5: unlock compatible Aqara locks from the thermostat screen; set up in the Aqara Home app. Provisional control value.
A14: aqara-w200.smart-home-device-scene-control-from-w200-panel | B14: aqara-w200 | C14: Aqara Thermostat Hub W200 | D14: thermostat | E14: Thermostat | F14: 14 | G14: runtime | H14: Smart-home device / scene control from W200 panel | I14: pat:deviceControlCommand | J14: pat:smartHomeControl | K14: ppd:transfer | L14: ppd:userProvided | M14: ppd:householdContext | O14: ck-6ce82887 | P14: user_initiated | Q14: optional | S14: Device and scene commands are sent only when you use the thermostat panel. | T14: source_linked | U14: aqara-w200.src5 | V14: device-control-command-smart-home-control-transfer-household-context | W14: Round 3: Necessity is inferred from what the flow does; no source states it. Earlier note: src5: controls lighting, curtain drivers, wall switches and scenes from one screen. Provisional control value.
A15: aqara-w200.aqara-zigbee-household-device-state-bridged-to-external | B15: aqara-w200 | C15: Aqara Thermostat Hub W200 | D15: thermostat | E15: Thermostat | F15: 15 | G15: runtime | H15: Aqara Zigbee / household device state bridged to external Matter ecosystems | I15: pat:householdDeviceState | J15: pat:ecosystemIntegration | K15: ppd:transfer | L15: ppd:householdProvided | M15: pat:smartHomeEcosystem | O15: ck-e07af878 | P15: user_setting | Q15: optional | R15: Matter binding: scan the QR code to bind; unbinding may disable schedules and other features | S15: You choose whether to connect the thermostat to a Matter ecosystem such as Apple Home; the manual says unbinding may turn off features such as schedules. | T15: source_linked | U15: aqara-w200.src5; aqara-w200.src6; aqara-w200.src8 | V15: household-device-state-ecosystem-integration-transfer-smart-home-ecosystem | W15: Round 3: Manual: Matter appears as a setup option ('Scan the QR code to bind'), several ecosystems can be added, and Matter unbinding 'may also disable schedules and other features'. MacRumors: the reviewer had to choose between Apple Home control or the Aqara app, which shows the thermostat works without an ecosystem. Not stated: whether the user can choose which Zigbee devices are shared with an ecosystem. Earlier note: src5: the W200 is a Zigbee hub and Matter bridge that connects Aqara Zigbee devices to Apple Home, Google Home and Alexa (it also lists SmartThings and Home Assistant). The page does not say which data is exposed or whether bridging is opt-in. Split into per-data-type flows once Aqara documentation says what is exposed.
A16: aqara-w200.control-command-received-from-external-matter-ecosystem | B16: aqara-w200 | C16: Aqara Thermostat Hub W200 | D16: thermostat | E16: Thermostat | F16: 16 | G16: runtime | H16: Control command received from external Matter ecosystem | I16: pat:deviceControlCommand | J16: pat:ecosystemIntegration | K16: ppd:collection | L16: pat:smartHomeEcosystemProvided | M16: ppd:householdContext | O16: ck-50df5684 | P16: user_setting | Q16: optional | R16: Matter binding: scan the QR code to bind; unbinding may disable schedules and other features | S16: Commands from a Matter ecosystem arrive only if you connect the thermostat to one, and you can unbind it. | T16: source_linked | U16: aqara-w200.src5; aqara-w200.src6; aqara-w200.src8 | V16: device-control-command-ecosystem-integration-collection-household-context | W16: Round 3: Same basis as the state-bridging row above. Commands can also come from ecosystem automations (for example Apple's Adaptive Temperature), so this is not user_initiated. Google Home and Alexa are not mentioned in the manual. Earlier note: src5: voice control via Siri/Alexa and direct connection to the listed platforms. Control (likely opt-in by adding the hub to an ecosystem) is not stated.
A17: aqara-w200.remote-thermostat-command-through-aqara-home-service | B17: aqara-w200 | C17: Aqara Thermostat Hub W200 | D17: thermostat | E17: Thermostat | F17: 17 | G17: runtime | H17: Remote thermostat command through Aqara Home service | I17: pat:thermostatControlCommand | J17: pat:remoteControl | K17: ppd:collection | L17: ppd:userProvided | M17: pat:aqaraService | O17: ck-b019ee2b | P17: user_initiated | Q17: optional | S17: A remote thermostat command is sent only when you send it from your phone. | T17: needs_source | U17: aqara-w200.src5; aqara-w200.src6 | V17: thermostat-control-command-remote-control-collection-aqara-service | W17: Round 3: Manual: mode and temperature settings are 'Adjustable in the app'. Control from outside the home network, and routing through the Aqara service, are not stated in the manual, the review or the forum guide, so evidence stays needs_source. Necessity is inferred from what the flow does; no source states it. Earlier note: src5 supports remote control from the phone, but routing through the Aqara Home service/cloud (handling_context aqaraService) is not stated, so evidence stays needs_source. Provisional control value.
A18: aqara-w200.device-diagnostics-logs-status-sent-to-aqara | B18: aqara-w200 | C18: Aqara Thermostat Hub W200 | D18: thermostat | E18: Thermostat | F18: 18 | G18: runtime | H18: Device diagnostics / logs / status sent to Aqara | I18: pat:diagnosticData | J18: ppd:diagnosticsAndMaintenance | K18: ppd:transfer | L18: ppd:participantGenerated | M18: pat:aqaraService | O18: ck-d0fc350e | P18: external_request | Q18: unknown | R18: You may withdraw your prior consent for the use of your personal data | S18: You can ask Aqara to delete your data or withdraw your consent by emailing privacy@Lumiunited.com; the policy describes no in-app switch for device logs. | T18: source_linked | U18: aqara-w200.src2 | V18: diagnostic-data-diagnostics-and-maintenance-transfer-aqara-service | W18: Round 3: Policy (src2) says it may collect 'device log, usage history and device status' and gives no opt-out for them. The only route is the general rights channel (consent withdrawal, deletion on request by email). The policy does not say whether a request stops device-level collection. General statement only: 'If you do not provide your personal information, we may not be able to provide you with our products or services' (not specific to diagnostics).
A19: aqara-w200.device-usage-history-sent-to-aqara-services | B19: aqara-w200 | C19: Aqara Thermostat Hub W200 | D19: thermostat | E19: Thermostat | F19: 19 | G19: runtime | H19: Device usage history sent to Aqara services | I19: ppd:usageData | J19: pat:usageEfficiency | K19: ppd:transfer | L19: ppd:participantGenerated | M19: pat:aqaraService | O19: ck-976049b7 | P19: external_request | Q19: unknown | R19: You may withdraw your prior consent for the use of your personal data | S19: You can ask Aqara to delete your data or withdraw your consent by emailing privacy@Lumiunited.com; the policy describes no in-app switch for usage history. | T19: source_linked | U19: aqara-w200.src2 | V19: usage-data-usage-efficiency-transfer-aqara-service | W19: Round 3: Policy lists 'usage history' among data collected from IoT devices with no opt-out; the only route is the general rights channel. Not stated whether a request stops collection, or whether any feature depends on usage history.
A20: aqara-w200.wi-fi-network-technical-telemetry-sent-to-aqara | B20: aqara-w200 | C20: Aqara Thermostat Hub W200 | D20: thermostat | E20: Thermostat | F20: 20 | G20: runtime | H20: Wi-Fi / network technical telemetry sent to Aqara | I20: pat:networkTelemetry | J20: ppd:diagnosticsAndMaintenance | K20: ppd:transfer | L20: ppd:participantGenerated | M20: pat:aqaraService | O20: ck-d0fc350e | P20: external_request | Q20: unknown | R20: You may withdraw your prior consent for the use of your personal data | S20: You can ask Aqara to delete your data or withdraw your consent by emailing privacy@Lumiunited.com; the policy describes no in-app switch for Wi-Fi information. | T20: source_linked | U20: aqara-w200.src2 | V20: network-telemetry-diagnostics-and-maintenance-transfer-aqara-service | W20: Round 3: Policy lists 'Wi-Fi List Information' among automatically collected data with no opt-out; only the general rights channel applies. Not stated whether a request stops collection or whether any feature depends on it.
A21: aqara-w200.mac-device-identifier-sent-to-aqara | B21: aqara-w200 | C21: Aqara Thermostat Hub W200 | D21: thermostat | E21: Thermostat | F21: 21 | G21: runtime | H21: MAC / device identifier sent to Aqara | I21: ppd:identifierData | J21: ppd:diagnosticsAndMaintenance | K21: ppd:transfer | L21: ppd:participantGenerated | M21: pat:aqaraService | O21: ck-f2c2d35a | P21: external_request | Q21: unknown | R21: You may withdraw your prior consent for the use of your personal data | S21: You can ask Aqara to delete your data or withdraw your consent by emailing privacy@Lumiunited.com; the policy describes no in-app switch for device identifiers. | T21: source_linked | U21: aqara-w200.src2 | V21: identifier-data-diagnostics-and-maintenance-transfer-aqara-service | W21: Round 3: Policy lists 'Mac address' among automatically collected data with no opt-out; only the general rights channel applies. A device identifier is plausibly needed to link the device to the account, but no page says so.
A22: aqara-w200.installation-pairing-location-metadata-device-location-region-city | B22: aqara-w200 | C22: Aqara Thermostat Hub W200 | D22: thermostat | E22: Thermostat | F22: 22 | G22: setup | H22: Installation / pairing location metadata (device location, region/city/timezone) | I22: ppd:locationData | J22: pat:deviceSetup | K22: ppd:collection | L22: ppd:userProvided | M22: pat:aqaraService | O22: ck-3a2fb945 | P22: setup_step | Q22: unknown | S22: Location details are provided during pairing or setup. | T22: source_linked | U22: aqara-w200.src2 | V22: location-data-device-setup-collection-aqara-service | W22: Round 3: Policy: 'We may need your location information for installing, activating and managing your Aqara devices.' The wording is hedged ('may need'), so necessity is left unknown rather than required_for_feature.
A23: aqara-w200.precise-mobile-geolocation-collected-for-location-based-analysis | B23: aqara-w200 | C23: Aqara Thermostat Hub W200 | D23: thermostat | E23: Thermostat | F23: 23 | G23: runtime | H23: Precise mobile geolocation collected for location-based analysis/marketing when separately consented | I23: ppd:locationData | J23: pat:locationBasedMarketing | K23: ppd:collection | L23: ppd:participantObserved | M23: pat:aqaraService | O23: ck-3795499e | P23: user_setting | Q23: optional | R23: when separately consented | S23: Precise location is collected only if you separately consent. | T23: source_linked | U23: aqara-w200.src2 | V23: location-data-location-based-marketing-collection-aqara-service | W23: Round 3: Necessity is inferred from what the flow does; no source states it.
A24: level-lock.setup-bluetooth-matter-pairing-credential-or-setup-code | B24: level-lock | C24: Level Lock (Smart Door Lock) | D24: smart_lock | E24: Smart door lock | F24: 2 | G24: setup | H24: Setup: Bluetooth/Matter pairing credential or setup code | I24: pat:pairingCredentialData | J24: pat:deviceSetup | K24: ppd:collection | L24: ppd:userProvided | M24: ppd:householdContext | O24: ck-8d3ef5b3 | P24: setup_step | Q24: required_for_feature | R24: add the lock | S24: You enter or scan the pairing/setup code when adding the lock. | T24: source_linked | U24: level-lock.src1; level-lock.src13; level-lock.src23 | V24: pairing-credential-data-device-setup-collection-household-context | W24: Round 3: src1 (Matter add-to-ecosystem article) and all other level.co/support/articles/* pages returned fetch errors every attempt, so not re-read. Control type kept (setup_step). Necessity inferred: the lock cannot be added to the Level Home app or a smart-home app without pairing. Apple supplement says to activate the lock in the Level Home app and to enable HomeKit at setup for Home Key; Seam-hosted manual says a HomeKit-first add needs a factory reset and there is a 30-minute window to add to the Level Home app (Level Lock+ HomeKit generation). Model note: Matter-generation locks (Level Lock+ Matter, Bolt, Lock, Lock Pro) use a Matter setup code; older Level Lock+ used a HomeKit code. Quote (from a summarised fetch, unverified): "Download the Level Home app on your iPhone, create an account, and follow the on-screen instructions to activate your lock." (Level-Lock-Plus_Supplement-For-Apple-Users.pdf)
A25: level-lock.setup-level-home-app-account-identifiers | B25: level-lock | C25: Level Lock (Smart Door Lock) | D25: smart_lock | E25: Smart door lock | F25: 3 | G25: setup | H25: Setup: Level Home app account identifiers | I25: ppd:identifierData | J25: pat:accountSetup | K25: ppd:collection | L25: ppd:userProvided | M25: pat:levelService | O25: ck-a323000c | P25: setup_step | Q25: required_for_feature | R25: create an account | S25: You create a Level account in the Level Home app when you set up your lock. | T25: source_linked | U25: level-lock.src2; level-lock.src6; level-lock.src13; level-lock.src22; level-lock.src12 | V25: identifier-data-account-setup-collection-level-service | W25: Round 3: Control type kept (setup_step). Necessity: Level's Apple supplement and Ring's Level setup page both say to create an account in the Level Home app to activate/set up the lock; feature = activating and using the lock through the Level Home app. Privacy statement says the account collects name, address, email and mobile number (wider than 'identifiers'). Recovery-key article: lock is linked to your account only; account deletion is by request; recovery key shown once and not stored by Level. Deletion/data-request channel: privacy@level.co or 1-833-453-8354. src2 not re-read (fetch error). Not checked: whether a Matter-only setup (no Level account) is possible. Quote (from a summarised fetch, unverified): "When you create a Level account, we collect and store your name, address, email address and mobile phone number." (legal)
A26: level-lock.household-member-guest-access-grant-and-role-assignment | B26: level-lock | C26: Level Lock (Smart Door Lock) | D26: smart_lock | E26: Smart door lock | F26: 4 | G26: runtime | H26: Household member / guest access grant and role assignment | I26: pat:householdMemberAccessGrant | J26: pat:accessSharing | K26: ppd:collection | L26: ppd:userProvided | M26: pat:levelService | O26: ck-f068902f | P26: user_initiated | Q26: optional | R26: share access | S26: This happens only when you choose to add someone as a household member or guest in the Level Home app. | T26: source_linked | U26: level-lock.src3; level-lock.src7; level-lock.src6; level-lock.src20 | V26: household-member-access-grant-access-sharing-collection-level-service | W26: Round 3: Sharing is an owner action; nothing flows if the owner does not add anyone. src3 (admin-vs-guest) could not be re-read (fetch error), so the exact role names/permissions are unverified here. Sharing story: guests added in app get 'always or temporary access'; keycard permissions can be removed via the app (verbatim); removal of app guests via the app per fetch summary only. Privacy statement frames it as optional ('may provide you with the ability'). Model note: event passes (time-limited) appear on Level Lock/Bolt/Pro pages; keypad needs the optional Keypad accessory. Necessity is inferred from what the flow does; no source states it. Quote (from a summarised fetch, unverified): "Level may provide you with the ability to share access to your Level Products and Services with other individuals" (legal)
A27: level-lock.lock-unlock-event-recorded-by-the-lock | B27: level-lock | C27: Level Lock (Smart Door Lock) | D27: smart_lock | E27: Smart door lock | F27: 5 | G27: runtime | H27: Lock/unlock event recorded by the lock | I27: ppd:usageData | J27: pat:accessControl | K27: ppd:collection | L27: pat:lockMechanism | M27: ppd:householdContext | O27: ck-79faaa81 | P27: none_documented | Q27: optional | T27: source_linked | U27: level-lock.src4; level-lock.src8; level-lock.src6; level-lock.src23 | V27: usage-data-access-control-collection-household-context | W27: Round 3: Feature depending on it: the activity history / last-action display. No setting to turn event recording off found. Checked: privacy statement (level.co/legal), Level Lock/Bolt/Pro product pages, Level Connect and Keypad datasheets, Level press releases, App Store listing, Seam-hosted manual. Only lever found: privacy statement says 'some information is processed and stored directly on the Level device' and can be deleted by resetting the device to defaults (a deletion, not a limit). CAVEAT: level.co/support/articles/* (incl. src4) returned fetch errors on every attempt, so a support-centre setting could exist. Not stated whether physical-key or auto-lock events are logged the same way; privacy says mechanical operation is recorded and communicated. Necessity set to optional: the lock still locks and unlocks without recording events; the activity-history display depends on it. Necessity is inferred from what the flow does; no source states it. Quote (from a summarised fetch, unverified): "View lock usage from your mobile app (unlocks/locks, users)" (Prosumer-Lock-Connect-Front-1.pdf)
A28: level-lock.lock-unlock-activity-communicated-to-level-services | B28: level-lock | C28: Level Lock (Smart Door Lock) | D28: smart_lock | E28: Smart door lock | F28: 6 | G28: runtime | H28: Lock/unlock activity communicated to Level services | I28: ppd:usageData | J28: pat:activityHistory | K28: ppd:transfer | L28: ppd:participantGenerated | M28: pat:levelService | N28: retention=ppd:indefinite | O28: ck-2e4b45cc | P28: external_request | Q28: optional | R28: communicates that information to the Level Services | S28: You can ask Level to access or delete your Level data by emailing privacy@level.co or calling 1-833-453-8354. | T28: source_linked | U28: level-lock.src4; level-lock.src6; level-lock.src8; level-lock.src9; level-lock.src19 | V28: usage-data-activity-history-transfer-level-service | W28: Round 3: Control channel is the privacy statement's data-request route (privacy@level.co / 1-833-453-8354) and account deletion; the statement does not say a request stops collection, only that data is kept 'until you choose to remove it or delete your account'. Necessity optional because Level says the lock works over Bluetooth without internet, and remote activity viewing needs the Level Connect Wi-Fi Bridge or a Matter-over-Thread hub (feature = viewing activity history from anywhere). Unclear whether the phone relays events to Level when no Connect/hub is present. RETENTION: no retention period for activity history found in any public source (privacy statement: stores personal information 'until you delete or edit it'; some data kept for legal/tax reasons). The row note that 'true retention is bounded' is not supported by what I could read. Model note: Level Connect (formerly Level Lock+ Connect) works with Lock+, Lock, Bolt and Pro; no difference found in this flow. Quote (from a summarised fetch, unverified): "it records and communicates that information to the Level Services so that you may see an updated status of your product." (legal) Earlier note: Placeholder: true retention is bounded, recorded as ppd:indefinite until a bounded-retention form is agreed.
A29: level-lock.activity-event-history-displayed-to-authorized-household-admins | B29: level-lock | C29: Level Lock (Smart Door Lock) | D29: smart_lock | E29: Smart door lock | F29: 7 | G29: runtime | H29: Activity event/history displayed to authorized household admins/users | I29: ppd:usageData | J29: pat:activityHistory | K29: ppd:use | L29: ppd:vendorProvided | M29: ppd:householdContext | O29: ck-7bfe63a4 | P29: none_documented | Q29: optional | T29: source_linked | U29: level-lock.src3; level-lock.src6; level-lock.src8; level-lock.src16; level-lock.src21 | V29: usage-data-activity-history-use-household-context | W29: Round 3: Feature = the activity history feed itself (advertised as standard: 'activity history'). No per-person or per-role setting to hide activity found; the only lever is the owner's choice of whom to add/remove (see row 4). Privacy statement says an Authorized User agrees the Owner may access information collected about their use. Checked: privacy statement, product pages, Level Connect/Keypad datasheets, App Store listing, press releases. CAVEAT: src3 (admin-vs-guest) and other support-centre pages were unreachable (fetch errors), so role-based visibility (e.g. whether guests see history) could not be confirmed. Necessity set to optional: the lock works without the activity feed; the feed itself is the feature that depends on it. Necessity is inferred from what the flow does; no source states it. Quote (from a summarised fetch, unverified): "access and use information collected in connection with your use of the Level Products and Services" (legal)
A30: level-lock.actor-method-identifier-displayed-with-access-event | B30: level-lock | C30: Level Lock (Smart Door Lock) | D30: smart_lock | E30: Smart door lock | F30: 8 | G30: runtime | H30: Actor / method identifier displayed with access event | I30: ppd:identifierData | J30: pat:activityHistory | K30: ppd:use | L30: ppd:vendorProvided | M30: ppd:householdContext | O30: ck-1388791b | P30: none_documented | Q30: unknown | T30: source_linked | U30: level-lock.src8; level-lock.src6; level-lock.src16 | V30: identifier-data-activity-history-use-household-context | W30: Round 3: Sources show the feed identifies users ('users' in Level's datasheet; names and profile photos shown to people you share access with). The method of entry (key code, fob, Home Key, app, physical key) is not confirmed by any source I could read. No setting to hide the actor identity found. Necessity unknown: no source says whether the history works without identifiers. CAVEAT: support-centre articles were unreachable (fetch errors). Quote (from a summarised fetch, unverified): "View lock usage from your mobile app (unlocks/locks, users)" (Prosumer-Lock-Connect-Front-1.pdf)
A31: level-lock.guest-authorized-user-contact-information-collected-for-access | B31: level-lock | C31: Level Lock (Smart Door Lock) | D31: smart_lock | E31: Smart door lock | F31: 9 | G31: runtime | H31: Guest / authorized-user contact information collected for access sharing | I31: ppd:identifierData | J31: pat:accessSharing | K31: ppd:collection | L31: ppd:userProvided | M31: pat:levelService | O31: ck-a323000c | P31: user_initiated | Q31: optional | R31: email address or mobile phone number | S31: This happens only when you choose to invite someone, and Level asks for their email address or mobile phone number to send the invitation. | T31: source_linked | U31: level-lock.src6; level-lock.src7 | V31: identifier-data-access-sharing-collection-level-service | W31: Round 3: Privacy statement states the contact detail request and that Level stores it to send the invitation, register the person if they accept, and track invitation success. Sharing story says app guests get an invitation to download the app and that keypad-code guests need no app, so no contact detail is needed for codes. The sharing story did not itself name which contact details are used. Not stated: how long invitee contact info is retained. Necessity is inferred from what the flow does; no source states it. Quote (from a summarised fetch, unverified): "We will ask you for the email address or mobile phone number of any such individuals" (legal)
A32: level-lock.pass-keypad-code-access-credential-provisioning | B32: level-lock | C32: Level Lock (Smart Door Lock) | D32: smart_lock | E32: Smart door lock | F32: 10 | G32: runtime | H32: Pass / keypad-code / access credential provisioning | I32: ppd:identifierData | J32: pat:accessSharing | K32: ppd:collection | L32: ppd:userProvided | M32: pat:levelService | O32: ck-a323000c | P32: user_initiated | Q32: optional | R32: Add people, passes, and Keypad codes on the Level App. | S32: This happens only when you choose to create a pass or keypad code for someone in the Level Home app. | T32: source_linked | U32: level-lock.src10; level-lock.src14; level-lock.src15; level-lock.src7; level-lock.src24; level-lock.src12 | V32: identifier-data-access-sharing-collection-level-service | W32: Round 3: Keypad is an optional accessory, so keypad codes are optional; passes/event passes are an optional sharing feature. Keypad datasheet says Level Connect enables remote operation and keypad code updates. Where codes are stored (lock vs Level cloud) is not stated, so handling_context pat:levelService is unverified. Factory reset 'clears any linked access credentials' (recovery-key article). Model note: Keypad is compatible with all Level locks; Level Lock Pro/Lock/Bolt pages mention event passes. Quote (from a summarised fetch, unverified): "Add people, passes, and Keypad codes on the Level App." (level-bolt)
A33: level-lock.mobile-geolocation-collected-for-home-away-boundary-features | B33: level-lock | C33: Level Lock (Smart Door Lock) | D33: smart_lock | E33: Smart door lock | F33: 11 | G33: runtime | H33: Mobile geolocation collected for Home/Away boundary features | I33: ppd:locationData | J33: pat:autoUnlock | K33: ppd:collection | L33: pat:mobileLocationService | M33: pat:levelService | O33: ck-83dae5df | P33: user_setting | Q33: optional | R33: you may choose to share location data | S33: You choose whether to share your phone's location with the Level app by granting location permission, and Auto-Unlock can be switched on or off in the lock's settings in the app. | T33: source_linked | U33: level-lock.src6; level-lock.src16; level-lock.src17 | V33: location-data-auto-unlock-collection-level-service | W33: Round 3: Level's privacy statement ties app location to arrive/leave-home notifications and says sharing is a choice; it does not name Auto-Unlock and does not say how to withdraw the permission. Auto-Unlock toggle and 'Always' location requirement come only from Trunetto (third party, not affiliated; seen on two fetches) so the second half of the control note rests on a secondary source. Apple privacy label (developer-declared, unverified by Apple) lists Precise and Coarse Location for App Functionality and Coarse Location for Analytics, linked to the user - analytics use of location is not described in the privacy statement. California notice lists 'precise geolocation of the Level Product' as sensitive personal information. Necessity optional: location is an opt-in permission and the lock still works without it; Auto-Unlock / arrival notifications are the features that need it. Model note: Auto lock/unlock listed for Level Lock, Lock+, Bolt and Lock Pro; MacRumors says Pro Auto Unlock 'uses Bluetooth and unlocks when you're in range'. Quote (from a summarised fetch, unverified): "For a better user experience in Level mobile apps, you may choose to share location data from your mobile device." (legal)
A34: level-lock.geofence-state-used-for-auto-unlock-touch-to | B34: level-lock | C34: Level Lock (Smart Door Lock) | D34: smart_lock | E34: Smart door lock | F34: 12 | G34: runtime | H34: Geofence state used for Auto Unlock / Touch to Unlock | I34: pat:geofenceState | J34: pat:autoUnlock | K34: ppd:use | L34: ppd:derivedFromPriorData | M34: pat:levelService | O34: ck-4daa844f | P34: user_setting | Q34: optional | R34: enable auto lock and unlock | S34: You can turn Auto-Unlock on or off in the lock's settings in the Level app. | T34: source_linked | U34: level-lock.src11; level-lock.src9; level-lock.src10; level-lock.src20; level-lock.src17; level-lock.src18 | V34: geofence-state-auto-unlock-use-level-service | W34: Round 3: Level's own pages describe Auto Lock/Unlock as an app feature users 'enable' and say it locks when you leave and unlocks when you return, but never mention a geofence; geofence details (about 200-300 m, set by the app; unlock sent over Bluetooth, 'not WiFi') and the toggle path (tap lock > Settings > Auto-Unlock) come only from Trunetto (third party). Evidence is therefore low-confidence for the 'geofence state' wording. HANDLING_CONTEXT looks questionable: Trunetto says the app sets the geofence and the command goes over Bluetooth, which suggests on-phone/lock processing rather than Level's service; no Level source says where the geofence is evaluated. CAVEAT: support article 'How to set up Auto Lock' (level.co/support/articles/how-to-set-up-auto-lock/) and others returned fetch errors. Quote (from a summarised fetch, unverified): "Automatically locks when you leave home and vice versa." (level-bolt)
A35: level-lock.home-address-zip-supplied-during-setup | B35: level-lock | C35: Level Lock (Smart Door Lock) | D35: smart_lock | E35: Smart door lock | F35: 13 | G35: setup | H35: Home address / ZIP supplied during setup | I35: ppd:locationData | J35: pat:deviceSetup | K35: ppd:collection | L35: ppd:userProvided | M35: pat:levelService | O35: ck-3a2fb945 | P35: setup_step | Q35: unknown | R35: we'll ask for information like your home address or ZIP code | S35: You enter your home address or ZIP code during setup. | T35: source_linked | U35: level-lock.src6; level-lock.src16 | V35: location-data-device-setup-collection-level-service | W35: Round 3: Privacy statement says setup asks for home address or ZIP, and says setup info is used to customise the experience, for example arrival notifications (paraphrase from fetch summary). No source says whether the field can be skipped or edited later, so necessity is unknown. Apple label lists Physical Address under Contact Info for App Functionality. Account creation separately collects 'address' per privacy statement - may overlap. California notice lists 'precise geolocation of the Level Product' as sensitive personal information. Control type kept (setup_step); editing later is unverified (support articles unreachable). Quote (from a summarised fetch, unverified): "For example, we'll ask for information like your home address or ZIP code, and to upload a photo of your door/home." (legal)
A36: level-lock.door-home-photo-supplied-during-setup | B36: level-lock | C36: Level Lock (Smart Door Lock) | D36: smart_lock | E36: Smart door lock | F36: 14 | G36: setup | H36: Door / home photo supplied during setup | I36: pat:visualData | J36: pat:deviceSetup | K36: ppd:collection | L36: ppd:userProvided | M36: pat:levelService | O36: ck-5e0af9dd | P36: setup_step | Q36: unknown | R36: upload a photo of your door/home | S36: You add a door or home photo during setup. | T36: source_linked | U36: level-lock.src6 | V36: visual-data-device-setup-collection-level-service | W36: Round 3: Same privacy-statement sentence as row 13; the photo's specific purpose is not separately stated and nothing says it can be skipped. Distinct from the optional account profile photo ('name and profile photo'), which is shown to people you share access with. Apple label lists no photo category (only 'Customer Support' user content), so storage on Level servers is not independently confirmed. Control type kept (setup_step); support articles unreachable. Quote (from a summarised fetch, unverified): "For example, we'll ask for information like your home address or ZIP code, and to upload a photo of your door/home." (legal)
A37: level-lock.remote-lock-unlock-command-through-level-app | B37: level-lock | C37: Level Lock (Smart Door Lock) | D37: smart_lock | E37: Smart door lock | F37: 15 | G37: runtime | H37: Remote lock/unlock command through Level app | I37: pat:lockControlCommand | J37: pat:remoteAccessControl | K37: ppd:collection | L37: ppd:userProvided | M37: pat:levelService | O37: ck-b019ee2b | P37: user_initiated | Q37: optional | R37: lock or unlock your door remotely | S37: This happens only when you send a lock or unlock command from the Level Home app while away, which needs a Level Connect Wi-Fi Bridge or a Matter-over-Thread hub. | T37: source_linked | U37: level-lock.src6; level-lock.src21; level-lock.src9; level-lock.src11; level-lock.src19; level-lock.src15 | V37: lock-control-command-remote-access-control-collection-level-service | W37: Round 3: Optional: Level says the lock keeps working over Bluetooth without internet; remote use is an add-on needing Level Connect or a Matter hub. Model/handling note: with a Matter hub (Apple Home/Google/Alexa) the remote path can run through the ecosystem and not Level's service (Level Bolt page: 'unlock your home remotely via Matter'; MacRumors: Level Connect not needed with HomePod/Apple TV), so handling_context pat:levelService only applies to the Level Connect path. Level Lock Pro/Lock/Bolt pages all state the requirement. Quote (from a summarised fetch, unverified): "lock or unlock your door remotely using the intuitive Level Home app" (convenience-level-lock-plus-connect)
A38: level-lock.lock-state-activity-returned-to-level-service | B38: level-lock | C38: Level Lock (Smart Door Lock) | D38: smart_lock | E38: Smart door lock | F38: 16 | G38: runtime | H38: Lock state / activity returned to Level service | I38: pat:lockState | J38: pat:remoteAccessControl | K38: ppd:transfer | L38: ppd:participantGenerated | M38: pat:levelService | O38: ck-5aedaaf3 | P38: external_request | Q38: optional | R38: see an updated status of your product | S38: You can ask Level to access or delete your Level data by emailing privacy@level.co or calling 1-833-453-8354. | T38: source_linked | U38: level-lock.src6; level-lock.src8; level-lock.src9 | V38: lock-state-remote-access-control-transfer-level-service | W38: Round 3: Privacy statement: operating the product mechanically or remotely is recorded and communicated to the Level Services so you see an updated status. Level Connect Wi-Fi Bridge adds real-time features such as knowing whether the door is open or closed (Lock Pro page); Level Connect is an optional accessory, so optional (feature = remote/real-time lock status). External-request channel is the generic data-request route; the statement does not say a request stops the status upload. Unclear whether phone-relayed (Bluetooth only) setups also upload state. Model note: door open/closed status is a Level Lock Pro sensor feature and may deserve its own row. Quote (from a summarised fetch, unverified): "it records and communicates that information to the Level Services so that you may see an updated status of your product." (legal)
A39: level-lock.matter-ecosystem-lock-unlock-command-received | B39: level-lock | C39: Level Lock (Smart Door Lock) | D39: smart_lock | E39: Smart door lock | F39: 17 | G39: runtime | H39: Matter ecosystem lock/unlock command received | I39: pat:lockControlCommand | J39: pat:ecosystemIntegration | K39: ppd:collection | L39: pat:smartHomeEcosystemProvided | M39: ppd:householdContext | O39: ck-50df5684 | P39: user_initiated | Q39: optional | R39: by phone, voice, or smart routine | S39: This happens only when you (or an automation you set up) send a lock or unlock command from a smart home app such as Apple Home, Google Home, Amazon Alexa or SmartThings. | T39: source_linked | U39: level-lock.src5; level-lock.src9; level-lock.src13; level-lock.src18; level-lock.src19; level-lock.src25 | V39: lock-control-command-ecosystem-integration-collection-household-context | W39: Round 3: src5 not re-read (fetch error); evidence kept. Level lists Apple Home, Google Home, Amazon Alexa and SmartThings via Matter-over-Thread; scenes can lock/unlock 'based on time or activity (through supported Matter platform)'. Necessity optional: Level Home app and Bluetooth/keys work without ecosystems; BUT Apple Home Key depends on enabling HomeKit at setup (Apple supplement), so Home Key users effectively need the Apple Home link. Model notes: Home Key is advertised for Level Lock+ and Level Lock Pro (Bolt page does not mention it); Level says an existing (older) Level Bolt cannot be updated to Matter, while current locks have Matter-over-Thread built in; non-Apple platforms need a Matter-over-Thread hub. Necessity is inferred from what the flow does; no source states it. Quote (from a summarised fetch, unverified): "Lock and unlock your door your way—by phone, voice, or smart routine." (level-lock-pro)
A40: level-lock.lock-state-shared-with-matter-ecosystem | B40: level-lock | C40: Level Lock (Smart Door Lock) | D40: smart_lock | E40: Smart door lock | F40: 18 | G40: runtime | H40: Lock state shared with Matter ecosystem | I40: pat:lockState | J40: pat:ecosystemIntegration | K40: ppd:transfer | L40: ppd:participantGenerated | M40: pat:smartHomeEcosystem | O40: ck-e8b6b621 | P40: user_initiated | Q40: optional | R40: Home app Activity log | S40: This happens only if you add your lock to a smart home app such as Apple Home, Google Home, Amazon Alexa or SmartThings. | T40: source_linked | U40: level-lock.src18; level-lock.src9; level-lock.src16 | V40: lock-state-ecosystem-integration-transfer-smart-home-ecosystem | W40: Round 3: Level's own pages never say in so many words that lock state is sent to the ecosystem; they say the lock works with these platforms and scenes can run 'based on time or activity'. The direct support is secondary: MacRumors (Level Lock Pro, Apple Home) says the Home app notifies when a connected lock is locked or unlocked and its Activity log records each lock/unlock. src1 (add-to-ecosystem article) was unreadable, so how to remove the lock from an ecosystem is not documented here and the control note makes no removal claim. Door open/closed status (Lock Pro) may also be shared and could be a separate row. Evidence upgraded with low-medium confidence. Necessity is inferred from what the flow does; no source states it. Quote (from a summarised fetch, unverified): "Home app Activity log keeps track of when each door was locked or unlocked" (level-lock-pro)
...

Sheet Devices
A1: Device ID | B1: Device | C1: Category ID | D1: Category | E1: Declaration device_id (example) | F1: Flows | G1: Declaration statements | H1: Device-level controls
A2: aqara-w200 | B2: Aqara Thermostat Hub W200 | C2: thermostat | D2: Thermostat | E2: aqara-w200-01 | F2: 22 | G2: 21
A3: level-lock | B3: Level Lock (Smart Door Lock) | C3: smart_lock | D3: Smart door lock | E3: level-lock-01 | F3: 21 | G3: 20
A4: lg-oled65c6pua-c6 | B4: LG OLED65C6PUA C6 (Smart TV, webOS) | C4: smart_tv | D4: Smart TV | E4: lg-oled65c6pua-c6-01 | F4: 19 | G4: 19
A5: reolink-e1-zoom | B5: Reolink E1 Zoom (PTZ Camera) | C5: camera | D5: Camera | E5: reolink-e1-zoom-01 | F5: 26 | G5: 24 | H5: Privacy Mode

Sheet Summary
A1: Device ID | B1: Device | C1: Category | D1: Flows | E1: Setup | F1: Runtime | G1: Control: user_setting | H1: Control: setup_step | I1: Control: user_initiated | J1: Control: external_request | K1: Control: none_documented | L1: Control: unknown | M1: Necessity: optional | N1: Necessity: required_for_feature | O1: Necessity: unknown | P1: Evidence: source_linked | Q1: Evidence: needs_source
A2: aqara-w200 | B2: Aqara Thermostat Hub W200 | C2: Thermostat | D2: =COUNTIFS(Flows!$B:$B,$A2) -> 22 | E2: =COUNTIFS(Flows!$B:$B,$A2,Flows!$G:$G,"setup") -> 4 | F2: =D2-E2 -> 18 | G2: =COUNTIFS(Flows!$B:$B,$A2,Flows!$P:$P,"user_setting") -> 5 | H2: =COUNTIFS(Flows!$B:$B,$A2,Flows!$P:$P,"setup_step") -> 5 | I2: =COUNTIFS(Flows!$B:$B,$A2,Flows!$P:$P,"user_initiated") -> 4 | J2: =COUNTIFS(Flows!$B:$B,$A2,Flows!$P:$P,"external_request") -> 5 | K2: =COUNTIFS(Flows!$B:$B,$A2,Flows!$P:$P,"none_documented") -> 3 | L2: =COUNTIFS(Flows!$B:$B,$A2,Flows!$P:$P,"unknown") -> 0 | M2: =COUNTIFS(Flows!$B:$B,$A2,Flows!$Q:$Q,"optional") -> 14 | N2: =COUNTIFS(Flows!$B:$B,$A2,Flows!$Q:$Q,"required_for_feature") -> 3 | O2: =COUNTIFS(Flows!$B:$B,$A2,Flows!$Q:$Q,"unknown") -> 5 | P2: =COUNTIFS(Flows!$B:$B,$A2,Flows!$T:$T,"source_linked") -> 21 | Q2: =COUNTIFS(Flows!$B:$B,$A2,Flows!$T:$T,"needs_source") -> 1
A3: level-lock | B3: Level Lock (Smart Door Lock) | C3: Smart door lock | D3: =COUNTIFS(Flows!$B:$B,$A3) -> 21 | E3: =COUNTIFS(Flows!$B:$B,$A3,Flows!$G:$G,"setup") -> 4 | F3: =D3-E3 -> 17 | G3: =COUNTIFS(Flows!$B:$B,$A3,Flows!$P:$P,"user_setting") -> 2 | H3: =COUNTIFS(Flows!$B:$B,$A3,Flows!$P:$P,"setup_step") -> 4 | I3: =COUNTIFS(Flows!$B:$B,$A3,Flows!$P:$P,"user_initiated") -> 6 | J3: =COUNTIFS(Flows!$B:$B,$A3,Flows!$P:$P,"external_request") -> 4 | K3: =COUNTIFS(Flows!$B:$B,$A3,Flows!$P:$P,"none_documented") -> 5 | L3: =COUNTIFS(Flows!$B:$B,$A3,Flows!$P:$P,"unknown") -> 0 | M3: =COUNTIFS(Flows!$B:$B,$A3,Flows!$Q:$Q,"optional") -> 13 | N3: =COUNTIFS(Flows!$B:$B,$A3,Flows!$Q:$Q,"required_for_feature") -> 3 | O3: =COUNTIFS(Flows!$B:$B,$A3,Flows!$Q:$Q,"unknown") -> 5 | P3: =COUNTIFS(Flows!$B:$B,$A3,Flows!$T:$T,"source_linked") -> 20 | Q3: =COUNTIFS(Flows!$B:$B,$A3,Flows!$T:$T,"needs_source") -> 1
A4: lg-oled65c6pua-c6 | B4: LG OLED65C6PUA C6 (Smart TV, webOS) | C4: Smart TV | D4: =COUNTIFS(Flows!$B:$B,$A4) -> 19 | E4: =COUNTIFS(Flows!$B:$B,$A4,Flows!$G:$G,"setup") -> 2 | F4: =D4-E4 -> 17 | G4: =COUNTIFS(Flows!$B:$B,$A4,Flows!$P:$P,"user_setting") -> 11 | H4: =COUNTIFS(Flows!$B:$B,$A4,Flows!$P:$P,"setup_step") -> 2 | I4: =COUNTIFS(Flows!$B:$B,$A4,Flows!$P:$P,"user_initiated") -> 4 | J4: =COUNTIFS(Flows!$B:$B,$A4,Flows!$P:$P,"external_request") -> 0 | K4: =COUNTIFS(Flows!$B:$B,$A4,Flows!$P:$P,"none_documented") -> 1 | L4: =COUNTIFS(Flows!$B:$B,$A4,Flows!$P:$P,"unknown") -> 1 | M4: =COUNTIFS(Flows!$B:$B,$A4,Flows!$Q:$Q,"optional") -> 15 | N4: =COUNTIFS(Flows!$B:$B,$A4,Flows!$Q:$Q,"required_for_feature") -> 2 | O4: =COUNTIFS(Flows!$B:$B,$A4,Flows!$Q:$Q,"unknown") -> 2 | P4: =COUNTIFS(Flows!$B:$B,$A4,Flows!$T:$T,"source_linked") -> 16 | Q4: =COUNTIFS(Flows!$B:$B,$A4,Flows!$T:$T,"needs_source") -> 3
A5: reolink-e1-zoom | B5: Reolink E1 Zoom (PTZ Camera) | C5: Camera | D5: =COUNTIFS(Flows!$B:$B,$A5) -> 26 | E5: =COUNTIFS(Flows!$B:$B,$A5,Flows!$G:$G,"setup") -> 5 | F5: =D5-E5 -> 21 | G5: =COUNTIFS(Flows!$B:$B,$A5,Flows!$P:$P,"user_setting") -> 18 | H5: =COUNTIFS(Flows!$B:$B,$A5,Flows!$P:$P,"setup_step") -> 4 | I5: =COUNTIFS(Flows!$B:$B,$A5,Flows!$P:$P,"user_initiated") -> 3 | J5: =COUNTIFS(Flows!$B:$B,$A5,Flows!$P:$P,"external_request") -> 0 | K5: =COUNTIFS(Flows!$B:$B,$A5,Flows!$P:$P,"none_documented") -> 1 | L5: =COUNTIFS(Flows!$B:$B,$A5,Flows!$P:$P,"unknown") -> 0 | M5: =COUNTIFS(Flows!$B:$B,$A5,Flows!$Q:$Q,"optional") -> 20 | N5: =COUNTIFS(Flows!$B:$B,$A5,Flows!$Q:$Q,"required_for_feature") -> 4 | O5: =COUNTIFS(Flows!$B:$B,$A5,Flows!$Q:$Q,"unknown") -> 2 | P5: =COUNTIFS(Flows!$B:$B,$A5,Flows!$T:$T,"source_linked") -> 23 | Q5: =COUNTIFS(Flows!$B:$B,$A5,Flows!$T:$T,"needs_source") -> 3
A6: Total | D6: =SUM(D2:D5) -> 88 | E6: =SUM(E2:E5) -> 15 | F6: =SUM(F2:F5) -> 73 | G6: =SUM(G2:G5) -> 36 | H6: =SUM(H2:H5) -> 15 | I6: =SUM(I2:I5) -> 17 | J6: =SUM(J2:J5) -> 9 | K6: =SUM(K2:K5) -> 10 | ... Q6: =SUM(Q2:Q5) -> 8
A8: Checks (should all be 0) | G8: =SUM(G6:L6)-D6 -> 0 | M8: =SUM(M6:O6)-D6 -> 0 | P8: =SUM(P6:Q6)-D6 -> 0
A9: Runtime = Flows minus 'setup' only, so the one 'setup+runtime' flow is counted under Runtime (same as before).

Sheet Core rule groups
A1: Core rule group | B1: data_type | C1: purpose | D1: action | E1: source | F1: handling_context | G1: Constraints | H1: Flows | I1: Devices (count) | J1: Device IDs
A2: ck-8d3ef5b3 | B2: ppd:deviceAndNetworkData | C2: ppd:coreFunctionality | D2: ppd:collection | E2: ppd:userProvided | F2: ppd:householdContext | H2: 6 | I2: 4 | J2: aqara-w200, level-lock, lg-oled65c6pua-c6, reolink-e1-zoom
A3: ck-a323000c | B3: ppd:identifierData | C3: ppd:coreFunctionality | D3: ppd:collection | E3: ppd:userProvided | F3: ppd:vendorContext | H3: 6 | I3: 4 | J3: aqara-w200, level-lock, lg-oled65c6pua-c6, reolink-e1-zoom
A4: ck-d0fc350e | B4: ppd:deviceAndNetworkData | C4: ppd:diagnosticsAndMaintenance | D4: ppd:transfer | E4: ppd:participantGenerated | F4: ppd:vendorContext | H4: 5 | I4: 3 | J4: aqara-w200, level-lock, lg-oled65c6pua-c6
A5: ck-42c4986b | B5: ppd:sensorData | C5: ppd:coreFunctionality | D5: ppd:collection | E5: ppd:participantObserved | F5: ppd:householdContext | H5: 3 | I5: 3 | J5: aqara-w200, lg-oled65c6pua-c6, reolink-e1-zoom
A6: ck-976049b7 | B6: ppd:usageData | C6: ppd:analyticsAndImprovement | D6: ppd:transfer | E6: ppd:participantGenerated | F6: ppd:vendorContext | H6: 3 | I6: 3 | J6: aqara-w200, lg-oled65c6pua-c6, reolink-e1-zoom
A7: ck-50df5684 | B7: ppd:deviceAndNetworkData | C7: ppd:coreFunctionality | D7: ppd:collection | E7: ppd:thirdPartyProvided | F7: ppd:householdContext | H7: 2 | I7: 2 | J7: aqara-w200, level-lock
A8: ck-b019ee2b | B8: ppd:deviceAndNetworkData | C8: ppd:coreFunctionality | D8: ppd:collection | E8: ppd:userProvided | F8: ppd:vendorContext | H8: 2 | I8: 2 | J8: aqara-w200, level-lock
A9: ck-5aedaaf3 | B9: ppd:deviceAndNetworkData | C9: ppd:coreFunctionality | D9: ppd:transfer | E9: ppd:participantGenerated | F9: ppd:vendorContext | H9: 2 | I9: 2 | J9: level-lock, reolink-e1-zoom
A10: ck-f2c2d35a | B10: ppd:identifierData | C10: ppd:diagnosticsAndMaintenance | D10: ppd:transfer | E10: ppd:participantGenerated | F10: ppd:vendorContext | H10: 2 | I10: 2 | J10: aqara-w200, level-lock
A11: ck-3a2fb945 | B11: ppd:locationData | C11: ppd:coreFunctionality | D11: ppd:collection | E11: ppd:userProvided | F11: ppd:vendorContext | H11: 2 | I11: 2 | J11: aqara-w200, level-lock
A12: ck-bb9073e6 | B12: ppd:usageData | C12: ppd:analyticsAndImprovement | D12: ppd:inference | E12: ppd:derivedFromPriorData | F12: ppd:vendorContext | H12: 2 | I12: 2 | J12: level-lock, lg-oled65c6pua-c6
A13: ck-4d01934b | B13: ppd:sensorData | C13: ppd:security | D13: ppd:inference | E13: ppd:derivedFromPriorData | F13: ppd:householdContext | G13: processing_boundary=ppd:onDeviceOnly | H13: 4 | I13: 1 | J13: reolink-e1-zoom
A14: ck-dcd0db95 | B14: ppd:contentData | C14: ppd:security | D14: ppd:collection | E14: ppd:participantObserved | F14: ppd:householdContext | H14: 2 | I14: 1 | J14: reolink-e1-zoom
